Workbook

Sheet 검색
B1: 보드게임 아레나 Ver. | J1: 코리아보드게임즈(공식) Ver.
A2: 종류 | B2: No. | C2: 이름 | D2: PWR 티어 | E2: wtdPWR | F2: 효과 | G2: 재료 | I2: 종류 | J2: No. | K2: 이름 | L2: PWR 티어 | M2: wtdPWR | N2: 효과 | O2: 재료
A3: 보조 설비 | B3: 1 | C3: 보조설비를 입력하세요 | D3: =VLOOKUP(검색!$C3,보조설비분석!$B$2:$G$354,5,FALSE) -> #N/A | E3: =VLOOKUP(검색!$C3,보조설비분석!$B$2:$G$354,6,FALSE) -> #N/A | F3: =VLOOKUP(검색!$C3,보조설비분석!$B$2:$E$354,3,FALSE) -> #N/A | G3: =VLOOKUP(검색!$C3,보조설비분석!$B$2:$E$354,4,FALSE) -> #N/A | I3: 보조 설비 | J3: 1 | K3: 보조설비를 입력하세요 | L3: =VLOOKUP(검색!$K3,보조설비분석!$C$2:$G$354,4,FALSE) -> #N/A | M3: =VLOOKUP(검색!$K3,보조설비분석!$C$2:$G$354,5,FALSE) -> #N/A | N3: =VLOOKUP(검색!$K3,보조설비분석!$C$2:$G$354,2,FALSE) -> #N/A | O3: =IF(IFERROR(VLOOKUP(검색!$K3,보조설비분석!$C$2:$G$354,1,FALSE),0)=0,VLOOKUP(검색!$K3,보조설비분석!$B$2:$G$354,4,FALSE),VLOOKUP(검색!$K3,보조설비분석!$C$2:$G$354,3,FALSE)) -> #N/A
B4: 2 | C4: 보조설비를 입력하세요 | D4: =VLOOKUP(검색!$C4,보조설비분석!$B$2:$G$354,5,FALSE) -> #N/A | E4: =VLOOKUP(검색!$C4,보조설비분석!$B$2:$G$354,6,FALSE) -> #N/A | F4: =VLOOKUP(검색!$C4,보조설비분석!$B$2:$E$354,3,FALSE) -> #N/A | G4: =VLOOKUP(검색!$C4,보조설비분석!$B$2:$E$354,4,FALSE) -> #N/A | J4: 2 | K4: 보조설비를 입력하세요 | L4: =VLOOKUP(검색!$K4,보조설비분석!$C$2:$G$354,4,FALSE) -> #N/A | M4: =VLOOKUP(검색!$K4,보조설비분석!$C$2:$G$354,5,FALSE) -> #N/A | N4: =VLOOKUP(검색!$K4,보조설비분석!$C$2:$G$354,2,FALSE) -> #N/A | O4: =IF(IFERROR(VLOOKUP(검색!$K4,보조설비분석!$C$2:$G$354,1,FALSE),0)=0,VLOOKUP(검색!$K4,보조설비분석!$B$2:$G$354,4,FALSE),VLOOKUP(검색!$K4,보조설비분석!$C$2:$G$354,3,FALSE)) -> #N/A
B5: 3 | C5: 보조설비를 입력하세요 | D5: =VLOOKUP(검색!$C5,보조설비분석!$B$2:$G$354,5,FALSE) -> #N/A | E5: =VLOOKUP(검색!$C5,보조설비분석!$B$2:$G$354,6,FALSE) -> #N/A | F5: =VLOOKUP(검색!$C5,보조설비분석!$B$2:$E$354,3,FALSE) -> #N/A | G5: =VLOOKUP(검색!$C5,보조설비분석!$B$2:$E$354,4,FALSE) -> #N/A | J5: 3 | K5: 보조설비를 입력하세요 | L5: =VLOOKUP(검색!$K5,보조설비분석!$C$2:$G$354,4,FALSE) -> #N/A | M5: =VLOOKUP(검색!$K5,보조설비분석!$C$2:$G$354,5,FALSE) -> #N/A | N5: =VLOOKUP(검색!$K5,보조설비분석!$C$2:$G$354,2,FALSE) -> #N/A | O5: =IF(IFERROR(VLOOKUP(검색!$K5,보조설비분석!$C$2:$G$354,1,FALSE),0)=0,VLOOKUP(검색!$K5,보조설비분석!$B$2:$G$354,4,FALSE),VLOOKUP(검색!$K5,보조설비분석!$C$2:$G$354,3,FALSE)) -> #N/A
B6: 4 | C6: 보조설비를 입력하세요 | D6: =VLOOKUP(검색!$C6,보조설비분석!$B$2:$G$354,5,FALSE) -> #N/A | E6: =VLOOKUP(검색!$C6,보조설비분석!$B$2:$G$354,6,FALSE) -> #N/A | F6: =VLOOKUP(검색!$C6,보조설비분석!$B$2:$E$354,3,FALSE) -> #N/A | G6: =VLOOKUP(검색!$C6,보조설비분석!$B$2:$E$354,4,FALSE) -> #N/A | J6: 4 | K6: 보조설비를 입력하세요 | L6: =VLOOKUP(검색!$K6,보조설비분석!$C$2:$G$354,4,FALSE) -> #N/A | M6: =VLOOKUP(검색!$K6,보조설비분석!$C$2:$G$354,5,FALSE) -> #N/A | N6: =VLOOKUP(검색!$K6,보조설비분석!$C$2:$G$354,2,FALSE) -> #N/A | O6: =IF(IFERROR(VLOOKUP(검색!$K6,보조설비분석!$C$2:$G$354,1,FALSE),0)=0,VLOOKUP(검색!$K6,보조설비분석!$B$2:$G$354,4,FALSE),VLOOKUP(검색!$K6,보조설비분석!$C$2:$G$354,3,FALSE)) -> #N/A
B7: 5 | C7: 보조설비를 입력하세요 | D7: =VLOOKUP(검색!$C7,보조설비분석!$B$2:$G$354,5,FALSE) -> #N/A | E7: =VLOOKUP(검색!$C7,보조설비분석!$B$2:$G$354,6,FALSE) -> #N/A | F7: =VLOOKUP(검색!$C7,보조설비분석!$B$2:$E$354,3,FALSE) -> #N/A | G7: =VLOOKUP(검색!$C7,보조설비분석!$B$2:$E$354,4,FALSE) -> #N/A | J7: 5 | K7: 보조설비를 입력하세요 | L7: =VLOOKUP(검색!$K7,보조설비분석!$C$2:$G$354,4,FALSE) -> #N/A | M7: =VLOOKUP(검색!$K7,보조설비분석!$C$2:$G$354,5,FALSE) -> #N/A | N7: =VLOOKUP(검색!$K7,보조설비분석!$C$2:$G$354,2,FALSE) -> #N/A | O7: =IF(IFERROR(VLOOKUP(검색!$K7,보조설비분석!$C$2:$G$354,1,FALSE),0)=0,VLOOKUP(검색!$K7,보조설비분석!$B$2:$G$354,4,FALSE),VLOOKUP(검색!$K7,보조설비분석!$C$2:$G$354,3,FALSE)) -> #N/A
B8: 6 | C8: 보조설비를 입력하세요 | D8: =VLOOKUP(검색!$C8,보조설비분석!$B$2:$G$354,5,FALSE) -> #N/A | E8: =VLOOKUP(검색!$C8,보조설비분석!$B$2:$G$354,6,FALSE) -> #N/A | F8: =VLOOKUP(검색!$C8,보조설비분석!$B$2:$E$354,3,FALSE) -> #N/A | G8: =VLOOKUP(검색!$C8,보조설비분석!$B$2:$E$354,4,FALSE) -> #N/A | J8: 6 | K8: 보조설비를 입력하세요 | L8: =VLOOKUP(검색!$K8,보조설비분석!$C$2:$G$354,4,FALSE) -> #N/A | M8: =VLOOKUP(검색!$K8,보조설비분석!$C$2:$G$354,5,FALSE) -> #N/A | N8: =VLOOKUP(검색!$K8,보조설비분석!$C$2:$G$354,2,FALSE) -> #N/A | O8: =IF(IFERROR(VLOOKUP(검색!$K8,보조설비분석!$C$2:$G$354,1,FALSE),0)=0,VLOOKUP(검색!$K8,보조설비분석!$B$2:$G$354,4,FALSE),VLOOKUP(검색!$K8,보조설비분석!$C$2:$G$354,3,FALSE)) -> #N/A
B9: 7 | C9: 보조설비를 입력하세요 | D9: =VLOOKUP(검색!$C9,보조설비분석!$B$2:$G$354,5,FALSE) -> #N/A | E9: =VLOOKUP(검색!$C9,보조설비분석!$B$2:$G$354,6,FALSE) -> #N/A | F9: =VLOOKUP(검색!$C9,보조설비분석!$B$2:$E$354,3,FALSE) -> #N/A | G9: =VLOOKUP(검색!$C9,보조설비분석!$B$2:$E$354,4,FALSE) -> #N/A | J9: 7 | K9: 보조설비를 입력하세요 | L9: =VLOOKUP(검색!$K9,보조설비분석!$C$2:$G$354,4,FALSE) -> #N/A | M9: =VLOOKUP(검색!$K9,보조설비분석!$C$2:$G$354,5,FALSE) -> #N/A | N9: =VLOOKUP(검색!$K9,보조설비분석!$C$2:$G$354,2,FALSE) -> #N/A | O9: =IF(IFERROR(VLOOKUP(검색!$K9,보조설비분석!$C$2:$G$354,1,FALSE),0)=0,VLOOKUP(검색!$K9,보조설비분석!$B$2:$G$354,4,FALSE),VLOOKUP(검색!$K9,보조설비분석!$C$2:$G$354,3,FALSE)) -> #N/A
B10: 8 | C10: 보조설비를 입력하세요 | D10: =VLOOKUP(검색!$C10,보조설비분석!$B$2:$G$354,5,FALSE) -> #N/A | E10: =VLOOKUP(검색!$C10,보조설비분석!$B$2:$G$354,6,FALSE) -> #N/A | F10: =VLOOKUP(검색!$C10,보조설비분석!$B$2:$E$354,3,FALSE) -> #N/A | G10: =VLOOKUP(검색!$C10,보조설비분석!$B$2:$E$354,4,FALSE) -> #N/A | J10: 8 | K10: 보조설비를 입력하세요 | L10: =VLOOKUP(검색!$K10,보조설비분석!$C$2:$G$354,4,FALSE) -> #N/A | M10: =VLOOKUP(검색!$K10,보조설비분석!$C$2:$G$354,5,FALSE) -> #N/A | N10: =VLOOKUP(검색!$K10,보조설비분석!$C$2:$G$354,2,FALSE) -> #N/A | O10: =IF(IFERROR(VLOOKUP(검색!$K10,보조설비분석!$C$2:$G$354,1,FALSE),0)=0,VLOOKUP(검색!$K10,보조설비분석!$B$2:$G$354,4,FALSE),VLOOKUP(검색!$K10,보조설비분석!$C$2:$G$354,3,FALSE)) -> #N/A
A12: 종류 | B12: No. | C12: 이름 | D12: PWR 티어 | E12: wtdPWR | F12: 효과 | I12: 종류 | J12: No. | K12: 이름 | L12: PWR 티어 | M12: wtdPWR | N12: 효과
A13: 직업 | B13: 1 | C13: 직업을 입력하세요 | D13: =VLOOKUP(검색!$C13,직업분석!$B$2:$F$345,4,FALSE) -> #N/A | E13: =VLOOKUP(검색!$C13,직업분석!$B$2:$F$345,5,FALSE) -> #N/A | F13: =VLOOKUP(검색!$C13,직업분석!$B$2:$D$345,3,FALSE) -> #N/A | I13: 직업 | J13: 1 | K13: 직업을 입력하세요 | L13: =VLOOKUP(검색!$K13,직업분석!$C$2:$F$345,3,FALSE) -> #N/A | M13: =VLOOKUP(검색!$K13,직업분석!$C$2:$F$345,4,FALSE) -> #N/A | N13: =VLOOKUP(검색!$K13,직업분석!$C$2:$F$345,2,FALSE) -> #N/A
B14: 2 | C14: 직업을 입력하세요 | D14: =VLOOKUP(검색!$C14,직업분석!$B$2:$F$345,4,FALSE) -> #N/A | E14: =VLOOKUP(검색!$C14,직업분석!$B$2:$F$345,5,FALSE) -> #N/A | F14: =VLOOKUP(검색!$C14,직업분석!$B$2:$D$345,3,FALSE) -> #N/A | J14: 2 | K14: 직업을 입력하세요 | L14: =VLOOKUP(검색!$K14,직업분석!$C$2:$F$345,3,FALSE) -> #N/A | M14: =VLOOKUP(검색!$K14,직업분석!$C$2:$F$345,4,FALSE) -> #N/A | N14: =VLOOKUP(검색!$K14,직업분석!$C$2:$F$345,2,FALSE) -> #N/A
B15: 3 | C15: 직업을 입력하세요 | D15: =VLOOKUP(검색!$C15,직업분석!$B$2:$F$345,4,FALSE) -> #N/A | E15: =VLOOKUP(검색!$C15,직업분석!$B$2:$F$345,5,FALSE) -> #N/A | F15: =VLOOKUP(검색!$C15,직업분석!$B$2:$D$345,3,FALSE) -> #N/A | J15: 3 | K15: 직업을 입력하세요 | L15: =VLOOKUP(검색!$K15,직업분석!$C$2:$F$345,3,FALSE) -> #N/A | M15: =VLOOKUP(검색!$K15,직업분석!$C$2:$F$345,4,FALSE) -> #N/A | N15: =VLOOKUP(검색!$K15,직업분석!$C$2:$F$345,2,FALSE) -> #N/A
B16: 4 | C16: 직업을 입력하세요 | D16: =VLOOKUP(검색!$C16,직업분석!$B$2:$F$345,4,FALSE) -> #N/A | E16: =VLOOKUP(검색!$C16,직업분석!$B$2:$F$345,5,FALSE) -> #N/A | F16: =VLOOKUP(검색!$C16,직업분석!$B$2:$D$345,3,FALSE) -> #N/A | J16: 4 | K16: 직업을 입력하세요 | L16: =VLOOKUP(검색!$K16,직업분석!$C$2:$F$345,3,FALSE) -> #N/A | M16: =VLOOKUP(검색!$K16,직업분석!$C$2:$F$345,4,FALSE) -> #N/A | N16: =VLOOKUP(검색!$K16,직업분석!$C$2:$F$345,2,FALSE) -> #N/A
B17: 5 | C17: 직업을 입력하세요 | D17: =VLOOKUP(검색!$C17,직업분석!$B$2:$F$345,4,FALSE) -> #N/A | E17: =VLOOKUP(검색!$C17,직업분석!$B$2:$F$345,5,FALSE) -> #N/A | F17: =VLOOKUP(검색!$C17,직업분석!$B$2:$D$345,3,FALSE) -> #N/A | J17: 5 | K17: 직업을 입력하세요 | L17: =VLOOKUP(검색!$K17,직업분석!$C$2:$F$345,3,FALSE) -> #N/A | M17: =VLOOKUP(검색!$K17,직업분석!$C$2:$F$345,4,FALSE) -> #N/A | N17: =VLOOKUP(검색!$K17,직업분석!$C$2:$F$345,2,FALSE) -> #N/A
B18: 6 | C18: 직업을 입력하세요 | D18: =VLOOKUP(검색!$C18,직업분석!$B$2:$F$345,4,FALSE) -> #N/A | E18: =VLOOKUP(검색!$C18,직업분석!$B$2:$F$345,5,FALSE) -> #N/A | F18: =VLOOKUP(검색!$C18,직업분석!$B$2:$D$345,3,FALSE) -> #N/A | J18: 6 | K18: 직업을 입력하세요 | L18: =VLOOKUP(검색!$K18,직업분석!$C$2:$F$345,3,FALSE) -> #N/A | M18: =VLOOKUP(검색!$K18,직업분석!$C$2:$F$345,4,FALSE) -> #N/A | N18: =VLOOKUP(검색!$K18,직업분석!$C$2:$F$345,2,FALSE) -> #N/A
B19: 7 | C19: 직업을 입력하세요 | D19: =VLOOKUP(검색!$C19,직업분석!$B$2:$F$345,4,FALSE) -> #N/A | E19: =VLOOKUP(검색!$C19,직업분석!$B$2:$F$345,5,FALSE) -> #N/A | F19: =VLOOKUP(검색!$C19,직업분석!$B$2:$D$345,3,FALSE) -> #N/A | J19: 7 | K19: 직업을 입력하세요 | L19: =VLOOKUP(검색!$K19,직업분석!$C$2:$F$345,3,FALSE) -> #N/A | M19: =VLOOKUP(검색!$K19,직업분석!$C$2:$F$345,4,FALSE) -> #N/A | N19: =VLOOKUP(검색!$K19,직업분석!$C$2:$F$345,2,FALSE) -> #N/A
B20: 8 | C20: 직업을 입력하세요 | D20: =VLOOKUP(검색!$C20,직업분석!$B$2:$F$345,4,FALSE) -> #N/A | E20: =VLOOKUP(검색!$C20,직업분석!$B$2:$F$345,5,FALSE) -> #N/A | F20: =VLOOKUP(검색!$C20,직업분석!$B$2:$D$345,3,FALSE) -> #N/A | J20: 8 | K20: 직업을 입력하세요 | L20: =VLOOKUP(검색!$K20,직업분석!$C$2:$F$345,3,FALSE) -> #N/A | M20: =VLOOKUP(검색!$K20,직업분석!$C$2:$F$345,4,FALSE) -> #N/A | N20: =VLOOKUP(검색!$K20,직업분석!$C$2:$F$345,2,FALSE) -> #N/A

Sheet 직업분석
A1: 번호 | B1: 이름 (아레나 Ver.) | C1: 이름 (공식 Ver.) | D1: 효과 | E1: wtd PWR티어 | F1: wtdPWR
A2: 1 | B2: 구걸하는 학생 | C2: 구걸하는 학생 | D2: - 이 카드를 내려놓을 때, 즉시 구걸 마커 1개를 받습니다. 매번 수확이 시작될 때마다, 비용을 내지 않고 직업 1개를 내려놓을 수 있습니다 | E2: S | F2: 6.22
A3: 2 | B3: 상업 교사 | C3: 사업 스승 | D3: - '교습' 행동 칸을 이용할 때마다 그 후에, 다음 물건들을 서로 다른 종류로 2개까지 구매할 수 있습니다: 곡식, 돌, 양, 멧돼지는 각각 비용으로 음식 1개씩을, 소, 채소는 각각 비용으로 음식 2개씩을 냅니다 | E3: S | F3: 5.85
A4: 3 | B4: 무자녀 | C4: 무자식 | D4: - 라운드가 시작될 때마다 방이 3개 이상인 집에 살지만 가족이 2명 뿐이라면, 음식 1개와 작물 1개(곡식이나 채소)를 가져올 수 있습니다 | E4: S | F4: 5.61
A5: 4 | B5: 잡화상인 | C5: 잡화상인 | D5: - 이 카드 위에 자원을 그림처럼 쌓습니다. 아무 때나, 맨 위에 있는 자원을 음식 1개를 내고 살 수 있습니다 (나무, 곡식, 갈대, 돌, 채소, 흙, 갈대, 채소) | E5: S | F5: 5.42
A6: 5 | B6: 가구상 | C6: 가구상 | D6: - 갱신: 이 카드를 내려놓으면 즉시 나무 2개를 가져옵니다. 방을 만들 때마다 각각 나무 1개씩을 덜 내고 설비를 내려놓을 수 있습니다 | E6: S | F6: 5.4
A7: 6 | B7: 밭일 감독 | C7: 밭일 감독 | D7: - 곡식 종자 행동 칸을 이용할 때, 밭 1개를 일굴 수 있습니다 | E7: S | F7: 5.35
A8: 7 | B8: 허풍선이 | C8: 허풍선이 | D8: - 점수를 계산할 때, 자기 앞에 놓여있는 설비가 5/6/7/8/9/10개 이상이라면 2/3/4/5/7/9점의 추가 점수를 받습니다 | E8: S | F8: 5.32
A9: 8 | B9: 정보원 | C9: 정보원 | D9: - 이 카드를 내려놓으면, 즉시 나무 1개를 가져옵니다. 일하기 단계가 끝날때마다, 개인 창고에 흙보다 돌이 더 많다면 나무 1개를 가져옵니다 | E9: S | F9: 5.18
A10: 9 | B10: 벽돌 까는 사람 | C10: 도로 포장공 | D10: - 매 준비 단계가 끝날 때마다, 개인 창고에 돌이 1개 이상 있다면 음식 1개를 가져옵니다. 14라운드에서는 음식 대신에 채소 1개를 가져옵니다 | E10: S | F10: 5.08
A11: 10 | B11: 보조 경작자 | C11: 보조 경작자 | D11: - '날품팔이' 이용 시, 밭 1개 일구기 | E11: S | F11: 4.99
A12: 11 | B12: 연인 | C12: 연인 | D12: - 이 카드를 내려놓을 때 즉시, 아직 시작하지 않은 라운드 수만큼의 음식을 내고 '빈 방이 없어도 가족 늘리기' 행동을 할 수 있습니다 | E12: 1 | F12: 4.95
A13: 12 | B13: 경작자 | C13: 경작자 | D13: - 새로 가져오는 밭 타일마다, 나무 1개와 음식 1개를 추가로 가져옵니다. | E13: 1 | F13: 4.93
A14: 13 | B14: 바구니 나르는 사람 | C14: 바구니 나르는 사람 | D14: - 수확 때마다 한 번씩, 음식 2개를 내고 나무 1개와 갈대 1개, 곡식 1개를 구매할 수 있습니다 | E14: 1 | F14: 4.91
A15: 14 | B15: 기능 장인 | C15: 기능 장인 | D15: - 이 카드를 놓을 때, 그리고 라운드 준비 단계에 돌 누적 행동 칸이 라운드 칸에 나타날 때마다, 나무 1개를 가져오고 '보조 설비' 행동을 얻습니다 | E15: 1 | F15: 4.78
A16: 15 | B16: 나무 교환하는 사람 | C16: 나무 교환하는 사람 | D16: - 울타리 치기나 방 만들기 행동이 포함된 행동 칸을 이용하기 전에, 나무 2개를 가져오거나 나무를 2개까지 내고 그 수만큼 갈대를 가져올 수 있습니다 | E16: 1 | F16: 4.71
A17: 16 | B17: 나무 오두막 늘리는 사람 | C17: 나무집 늘리는 사람 | D17: - 나무집 방의 비용이 5라운드까지는 갈대 1개와 나무 5개, 6~7라운드에는 갈대 1개와 나무 4개, 8라운드에는 갈대 1개와 나무 3개가 됩니다 | E17: 1 | F17: 4.7
A18: 17 | B18: 석공 | C18: 석공 | D18: - 이 카드 위에 돌집 방 1개를 놓습니다. 게임 중 1번, 방이 4개 이상 있는 돌집을 가지고 있을 때 아무 때나, 건축 자원을 내지 않고 이 카드 위의 방을 만들 수 있습니다. | E18: 1 | F18: 4.67
A19: 18 | B19: 숲 평가원 | C19: 숲 평론가 | D19: - 아무 플레이어(이 카드를 낸 플레이어 포함)나 비어있는 '수풀'/'숲' 누적 칸을 이용할 때마다 그 직후에 '숲'/'수풀' 행동 칸이 이미 사용 중이라면, 당신은 갈대 1개를 가져옵니다 | E19: 1 | F19: 4.62
A20: 19 | B20: 굴뚝 청소부 | C20: 굴뚝 청소부 | D20: - 돌집으로 집을 고칠 때 비용으로 돌2개를 적게 냅니다. 점수를 계산할떄, 돌집에 살고 있는 다른 플레이어 1명마다 추가점수 1점을 받습니다 | E20: 1 | F20: 4.59
A21: 20 | B21: 집 고치는 숙련공 | C21: 숙련된 집 고치는 사람 | D21: - 이 카드를 내려놓으면 즉시 나무 1개와 흙 1개를 가져옵니다. 집을 고친 후에, 그 라운드에 놓은 가족 구성원의 수만큼 나무를 가져옵니다 | E21: 1 | F21: 4.58
A22: 21 | B22: 소의 왕자 | C22: 소의 왕자 | D22: - 점수를 계산할 때, 적어도 1마리의 소를 키우고 있는 농장 칸마다(방도 포함) 추가점수 1점씩을 받습니다 | E22: 1 | F22: 4.58
A23: 22 | B23: 실 잣는 사람 | C23: 실 잣는 사람 | D23: - 자신을 포함한 누군가가 '갈대밭' 누적 행동 칸에서 갈대를 2개 이상 가져올때마다, 곡식 1개를 가져오거나 음식 2개 내고 채소 1개를 구입 가능 | E23: 1 | F23: 4.49
... A266: 265 | B266: 수다쟁이 | C266: 수다쟁이 | D266: - 누적 칸에서 건축 자원을 4개 이상 가져오거나, 가축을 4마리 이상 가져올 때마다, 음식 1개를 추가로 가져옵니다 | E266: 5 | F266: 0
A267: 266 | B267: 가을의 어머니 | C267: 가을의 어머니 | D267: - 수확을 하기 직전에, 집에 빈 방이 있다면 음식 3개를 내고 '가족 늘리기' 행동을 할 수 있습니다 | E267: 없음
A268: 267 | B268: 현장 관리자 | C268: 현장 관리자 | D268: - 이 카드를 놓을 때 3/6/9번의 라운드가 남았다면 나무 2/3/4개를 가져옵니다. 점수를 계산할 때, 모든 종류의 건축 자원을 1/2/3개 이상 모은 플레이어는 모두 추가점수 1/3/5점씩을 받습니다 | E268: 없음
A269: 268 | B269: 수공예 교사 | C269: 수공예 교사 | D269: - 주요 설비 '가구 제작소'나 '그릇 제작소' 혹은 '바구니 제작소'를 지을 때마다, 그 직후에 비용을 내지 않고 직업을 2장까지 내려놓을 수 있습니다 | E269: 없음
A270: 269 | B270: 요리 전문가 | C270: 요리 전문가 | D270: - 다른 플레이어가 '유랑극단' 누적 행동 칸을 이용할 때마다, 곡식/양/채소 중 원하는 자원 1개를 음식 4/5/7개로 바꿀 수 있습니다 | E270: 없음
A271: 270 | B271: 밭 경작자 | C271: 밭 경작자 | D271: - 이 카드 위에 밑에서부터 나무 1개, 흙 1개, 갈대 1개, 돌 1개, 갈대 1개, 흙 1개, 나무 1개를 순서대로 쌓습니다. 밭 타일에서 수확할 때마다, 맨 위에 있는 물건 1개를 가져올 수 있습니다 | E271: 없음
A272: 271 | B272: 농경 대장 | C272: 농경 대장 | D272: - 다른 플레이어가 이미 놓여있는 밭 타일 옆에 새로운 밭 타일을 놓을 때마다, 당신은 그렇게 놓은 밭 타일마다 공동 창고에서 음식 1개씩을 가져옵니다. 14라운드에서는 음식 대신 곡식 1개씩을 가져옵니다 | E272: 없음
A273: 272 | B273: 종자 연구원 | C273: 종자 연구원 | D273: - 집에 돌아오기 단계에 '곡식 종자'와 '채소 종자' 행동 칸에서 돌아오는 가족 구성원(누구의 가족이든 상관없이) 둘 다 있다면, 음식 2개를 가져오고 직업 비용 없이 직업 1개를 놓을 수 있습니다 | E273: 없음
A274: 273 | B274: 침대 제작자 | C274: 침대 제작자 | D274: - 방을 만들 때마다, 나무 1개와 곡식 1개를 추가로 내고 즉시 '빈 방이 있어야만 가족 늘리기' 행동을 1번할 수 있습니다 | E274: 없음
A275: 274 | B275: 제작소 조수 | C275: 제작소 조수 | D275: - 서로 다른 건축 자원 2개로 이루어진 서로 다른 조합들을 만들어 당신의 각 설비에 올려놓습니다. 다른 플레이어가 집을 고칠 때마다, 설비에 놓여있는 건축 자원 조합 1개를 골라 개인 창고로 가져옵니다 | E275: 없음
A276: 275 | B276: 방목 농부 | C276: 방목 농부 | D276: - 이 카드를 내려놓을 때, 개인 창고에 외양간이 적어도 3개 있다면, 이 외양간 3개를 게임으로부터 제거하고, 2칸을 차지하도록 우리를 짓습니다. 이때 울타리 비용으로 나무 2개만 냅니다 | E276: 없음
A277: 276 | B277: 은신처 건축가 | C277: 은신처 건축가 | D277: - 게임 중 한 번, 흙집이나 돌집에 살고 있을 때 곡식 1개와 음식 2개를 낼 수 있습니다. 그렇게 한다면, 남은 게임 동안 이 카드는 가족 구성원 1명을 위한 방을 제공합니다 | E277: 없음
A278: 277 | B278: 자택 경비원 | C278: 자택 경비원 | D278: - 우리와 밭에 동시에 인접한 흙방이나 돌방 딱 1개에 추가로 가족 1명을 더 수용할 수 있습니다. | E278: 없음
... A337: 336 | B337: 술집 주인(a) | C337: 술집 주인 | D337: - 다른 플레이어가 '조건 없는 씨 뿌리기' 행동을 할 때마다, 그 직전에 그 플레이어에게 곡식 1개를 주고 추가 점수 1점을 받을 수 있습니다 | E337: 없음
A338: 337
A339: 338
A340: 339
...

Sheet 보조설비분석
A1: 번호 | B1: 이름 (아레나 Ver.) | C1: 이름 (공식 Ver.) | D1: 효과 | E1: 재료 | F1: WtdPWR 티어 | G1: WtdPWR
A2: 1 | B2: 외바퀴 쟁기 | C2: 이랑 쟁기 | D2: - [직업 3개] 이 카드 위에 밭 타일 4개를 놓습니다. 농지 행동 칸을 이용할 때, 이 카드의 밭 2개를 일굴 수 있습니다. | E2: [직업 3개] 3나무 | F2: S | G2: 5.85
A3: 2 | B3: 가로로 자른 나무 | C3: 가로로 자른 나무 | D3: - 즉시 개인 창고에 있는 돌의 개수만큼 나무를 가져옵니다 | E3: [직업 3개] 1음식 | F3: S | G3: 5.71
A4: 3 | B4: 교사의 책상 | C4: 교사의 책상 | D4: - [직업 1개] '주요 설비'나 '집 개조' 행동 칸을 이용할때, 직업 비용으로 음식 1개를 내고 직업 1개를 내려놓을 수 있습니다 | E4: [직업 1개] 1나무 | F4: S | G4: 5.47
A5: 4 | B5: 목수의 객실 | C5: 목수의 객실 | D5: - 나무집에 방을 만들 때 방 1개당 나무 2개, 갈대 2개만 냅니다 | E5: 1나무 1돌 | F5: S | G5: 5.31
A6: 5 | B6: 양토 채굴장 | C6: 양토 채굴장 | D6: - [직업 3개] '날품팔이' 행동 칸을 이용할 때, 흙 3개를 추가로 가져옵니다 | E6: [직업 3개] 1음식 | F6: S | G6: 5.22
A7: 6 | B7: 철물점 | C7: 철물점 | D7: - 날품팔이 행동 칸을 이용할 때마다, 그 후에 음식 2개를 내고 나무 1개, 흙 1개, 갈대 1개, 돌 1개를 구매할 수 있습니다. | E7: 1나무 1흙 | F7: S | G7: 5.21
A8: 7 | B8: 상추밭 | C8: 상추밭 | D8: - [직업 3개] 이 카드는 채소만 심을 수 있는 밭으로 기능을 합니다. 이 카드에서 수확한 채소는 즉시 음식 4개로 바꿀 수 있습니다 | E8: [직업 3개] | F8: S | G8: 5.17
A9: 8 | B9: 재직 증명서 | C9: 재직 증명서 | D9: - 행동 칸을 사용할 때마다, 그 직후에 건축 자원이 4개 이상 올려진 건축 자원 누적 행동 칸에서 건축 자원 1개를 가져올 수 있습니다. | E9: [직업 3개] 1음식 | F9: S | G9: 5.09
A10: 9 | B10: 책장 | C10: 책꽂이 | D10: - [직업 3개] 직업을 내려놓을 때, 직업 비용을 내기 전에 음식 3개를 가져옵니다. | E10: [직업 3개] 1나무 | F10: S | G10: 5.08
A11: 10 | B11: 포장마차 | C11: 포장마차 | D11: - 이 카드는 가족 구성원 1명을 위한 방을 제공합니다 | E11: 3나무 3음식 | F11: 1 | G11: 4.92
A12: 11 | B12: 다진 흙 | C12: 다진 흙 | D12: - 이 카드를 내려놓으면 즉시 흙 1개를 가져옵니다. 울타리를 칠 때 나무대신 흙을 낼 수 있습니다. | E12: - | F12: 1 | G12: 4.86
A13: 12 | B13: 책꽂이 | C13: 책장 | D13: - [직업 1개] 직업을 내려놓을 때마다 채소 1개를 가져옵니다. | E13: [직업 1개] 2나무 | F13: 1 | G13: 4.85
A14: 13 | B14: 추수용 낫 | C14: 추수용 낫 | D14: - 4, 7, 9, 11, 13, 14라운드 중에 순서대로 다음에 오는 라운드 칸 3개에 곡식 1개씩을 놓습니다. 해당 라운드가 시작될 때마다 이 곡식을 가져옵니다 | E14: 1나무 | F14: 1 | G14: 4.8
A15: 14 | B15: 밭 울타리 | C15: 밭 울타리 | D15: - 즉시 울타리 치기 행동을 이용할 수 있습니다. 이 행동으로 울타리를 칠 때 밭타일 옆에 치는 울타리에는 나무를 내지 않습니다 | E15: 2음식 | F15: 1 | G15: 4.75
A16: 15 | B16: 양날쟁기 | C16: 회전식 쟁기 | D16: - [직업 2개] 이 카드 위에 밭 타일 2개를 놓습니다. 농지나 밭 농사 행동 칸을 이용할 때, 이 카드의 밭 2개를 일굴 수 있습니다. | E16: [직업 2개] 3나무 | F16: 1 | G16: 4.73
A17: 16 | B17: 젖짜기 의자 | C17: 젖짜기 의자 | D17: - [직업 2개] 수확 중 농장 단계에서, 소를 1/3/5마리 이상 갖고 있다면 음식 1/2/3개를 가져옵니다. 점수를 계산할 때, 소 2마리당 추가 1점씩을 받습니다. | E17: [직업 2개] 1나무 | F17: 1 | G17: 4.69
A18: 17 | B18: 흙집 골조 | C18: 흙집 골조 | D18: - 흙집 방을 만들 때 흙 5개와 갈대 2개 대신 흙 2개, 나무 1개, 갈대 1개를 낼 수 있습니다. | E18: 2나무 | F18: 1 | G18: 4.69
A19: 18 | B19: 교육 수당 | C19: 교육 성과급 | D19: - [설비 2개] 1/2/3/4/5/6번째 직업을 내려놓을 때 즉시 곡식/흙/갈대/돌/채소/밭 1개를 가져옵니다 (이미 내려놓은 직업에 대한 혜택은 받지 않습니다) | E19: [설비 2개] 1음식 | F19: 1 | G19: 4.69
A20: 19 | B20: 수확 창고 | C20: 수확 창고 | D20: - 이 카드를 내려놓을 때, 완료한 수확의 횟수가 당신이 내려놓은 직업의 개수와 같다면, 즉시 음식 1개와 곡식 1개, 채소 1개를 가져옵니다 | E20: 1나무 1흙 1갈대 | F20: 1 | G20: 4.62
A21: 20 | B21: 채굴 망치 | C21: 채굴 망치 | D21: - 이 카드를 내려놓으면 즉시 음식 1개를 가져옵니다. 집을 고칠 때, 나무를 내지 않고 외양간 1개를 지을 수 있습니다 | E21: 1나무 | F21: 1 | G21: 4.57
A22: 21 | B22: 베틀 | C22: 베틀 | D22: - [직업 2개] 수확 중 농장 단계에서, 양 1/4/7마리를 가지고 있으면 음식 1/2/3개를 가져옵니다. 점수를 계산할 때, 양 3마리당 추가점수 1점씩을 받습니다 | E22: [직업 2개] 2나무 | F22: 1 | G22: 4.56
... A248: 247 | B248: 발톱 칼 | C248: 발톱 칼 | D248: - [우리 딱 1개] '양 시장' 누적 행동 칸을 이용할 때마다, 다음 라운드 칸 2개에 음식 1개씩을 놓습니다. 해당 라운드가 시작될 때마다, 이 음식을 가져옵니다 | E248: [우리 딱 1개] 1나무 | F248: 5 | G248: 0.04
A249: 248 | B249: 모집 | C249: 모집 | D249: - [집에 남아있는 가족 구성원이 없다면] 집에 빈 방이 있다면, '보조 설비 내리기' 행동을 할 때마다, '가족 늘리기' 행동을 대신 할 수 있습니다 | E249: [집에 남아있는 가족 구성원이 없다면] 1음식 | F249: 없음
A250: 249 | B250: 우물 | C250: 우물 | D250: - 4점. 다음 라운드 칸 5개에 음식을 1개씩 놓습니다. 해당 라운드가 시작될 때마다, 이 음식을 가져옵니다. | E250: 3돌/1나무 | F250: 주요 설비
A251: 250 | B251: 맥주 양조장 | C251: 맥주 양조장 | D251: - 매 수확의 가족 먹여살리기 단계에서 한 번씩, 이 카드를 이용하여 개인 창고의 곡식 1개와 밭에 심어진 곡식 1개를 추가점수 2점과 음식 4개로 바꿀 수 있습니다 | E251: 2나무 1흙 | F251: 없음
A252: 251 | B252: 여름 별장 | C252: 여름 별장 | D252: - [나무집에 살고 있다면] 점수를 계산할 때 당신이 돌집에 살고 있다면, 집에 인접한 사용하지 않은 농장 칸 1개마다 추가점수 2점씩을 받습니다. (여전히 사용하지 않은 빈칸으로 인한 감점을 받습니다) | E252: [나무집에 살고 있다면] 3나무 1돌 | F252: 없음
A253: 252 | B253: 아치형 입구 | C253: 아치형 입구 | D253: - [직업 없음] 이 카드는 모든 플레이어가 이용할 수 있는 행동 칸입니다. 이 행동 칸을 이용하는 플레이어는 즉시 음식 1개를 가져옵니다. 집에 돌아오기 단계 직전에, 해당 플레이어는 이 카드에 놓인 가족 구성원을 비어있는 행동 칸으로 옮긴 후 그 행동 칸을 이용할 수 있습니다 | E253: [직업 없음] 2흙 | F253: 없음
A254: 253 | B254: 시장 가판대 | C254: 시장 가판대 | D254: - (비용으로 당신의 개인 창고에 있는 외양간 1개를 게임으로부터 제거합니다.) 매 수확의 농장 단계가 끝난 후에, 개인 창고에 있는 울타리 1개와 곡식 1개를 음식 5개로 바꿀 수 있습니다(사용한 울타리는 게임에서 제거합니다) | E254: 1외양간(개인창고) | F254: 없음
A255: 254 | B255: 도예가 안뜰 | C255: 도예가 안뜰 | D255: - [농장에 빈칸 7칸 이하] 이 카드를 내려놓으면 즉시 내 농장 빈칸에 흙을 1개씩 놓습니다. 이후 빈칸을 채울 때마다, 그 칸에 놓인 흙을 가져옵니다. 또한 이렇게 가져온 흙을 즉시 음식 2개로 바꿀 수 있습니다 | E255: [농장에 빈칸 7칸 이하] 1나무 1갈대 | F255: 없음
A256: 255 | B256: 화덕 확장 | C256: 화덕 확장 | D256: - 수확 때마다, 당신의 화로 계열 설비를 각각 한 번씩 이용해, 가축 1마리나 채소 1개를 두 배의 음식으로 바꿀 수 있습니다 | E256: 2흙 | F256: 없음
A257: 256 | B257: 자재 중심지 | C257: 자재 중심지 | D257: - [개인 창고에 1갈대와 1돌] 이 카드 위에 건축 자원을 종류별로 2개씩 놓습니다. 누구든 (이 카드를 낸 플레이어 포함) 적어도 행동 칸에서 나무 5개나 흙 4개, 갈대 3개, 돌 3개를 가져갈 때마다, 당신은 해당되는 건축 자원 1개를 이 카드에서 가져랍니다 | E257: [개인 창고에 1갈대와 1돌] 1나무 1흙 | F257: 없음
A258: 257 | B258: 예배당 | C258: 예배당 | D258: - [직업 2개] 예배당은 모두가 쓸 수 있는 행동 칸입니다. 예배당을 이용하는 플레이어는 추가점수 3점을 받습니다. 다른 플레이어가 예배당을 이용할 경우 예배당 주인에게 곡식 1개를 내야 합니다 | E258: [직업 2개] 3나무 2흙 | F258: 없음
A259: 258 | B259: 집필실 | C259: 집필실 | D259: - 점수를 계산할 때, 감점만큼의 추가 점수를 받습니다. 이 추가점수는 최대 7점까지 받을 수 있습니다 | E259: 2나무 | F259: 없음
A260: 259 | B260: 짚 거름 | C260: 짚 거름 | D260: - [밭 2개] 매 수확마다 농장 단계 직전에, 개인 창고의 곡식 1개를 내고, 최대 2곳까지의 채소밭에 각각 채소 1개씩을 더할 수 있습니다 | E260: [밭 2개] | F260: 없음
... A348: 347 | B348: 언덕 위의 집 | C348: 언덕 위의 집 | D348: - [3라운드 이전] 앞으로 농장에 새로 놓는 밭 타일 1개마다 음식 1개를 내야만 합니다. | E348: 1음식 | F348: 없음
A349: 348
A350: 349
A351: 350
A352: 351
...
